<?xml version="1.0" encoding="UTF-8"?>
<!-- Generated by org.testng.reporters.JUnitReportReporter -->
<testsuite hostname="Жожа-ПК" name="myApplicationTest.TestSuiteAllTests" tests="11" failures="2" timestamp="15 Jul 2015 16:29:07 GMT" time="1.041" errors="1">
  <testcase name="EmployeeTest7" time="0.000" classname="myApplicationTest.TestSuiteAllTests"/>
  <testcase name="EmployeeTest" time="0.010" classname="myApplicationTest.TestSuiteAllTests"/>
  <testcase name="EmployeeTest2" time="0.000" classname="myApplicationTest.TestSuiteAllTests"/>
  <testcase name="EmployeeTest5" time="0.000" classname="myApplicationTest.TestSuiteAllTests">
    <failure type="java.lang.AssertionError" message="expected [1001] but found [100001]">
      <![CDATA[java.lang.AssertionError: expected [1001] but found [100001]
	at org.testng.Assert.fail(Assert.java:94)
	at org.testng.Assert.failNotSame(Assert.java:492)
	at org.testng.Assert.assertSame(Assert.java:443)
	at org.testng.Assert.assertSame(Assert.java:453)
	at myApplicationTest.TestSuiteAllTests.EmployeeTest5(TestSuiteAllTests.java:56)
	at sun.reflect.NativeMethodAccessorImpl.invoke0(Native Method)
	at sun.reflect.NativeMethodAccessorImpl.invoke(Unknown Source)
	at sun.reflect.DelegatingMethodAccessorImpl.invoke(Unknown Source)
	at java.lang.reflect.Method.invoke(Unknown Source)
	at org.testng.internal.MethodInvocationHelper.invokeMethod(MethodInvocationHelper.java:85)
	at org.testng.internal.Invoker.invokeMethod(Invoker.java:648)
	at org.testng.internal.Invoker.invokeTestMethod(Invoker.java:834)
	at org.testng.internal.Invoker.invokeTestMethods(Invoker.java:1142)
	at org.testng.internal.TestMethodWorker.invokeTestMethods(TestMethodWorker.java:124)
	at org.testng.internal.TestMethodWorker.run(TestMethodWorker.java:108)
	at org.testng.TestRunner.privateRun(TestRunner.java:771)
	at org.testng.TestRunner.run(TestRunner.java:621)
	at org.testng.SuiteRunner.runTest(SuiteRunner.java:357)
	at org.testng.SuiteRunner.runSequentially(SuiteRunner.java:352)
	at org.testng.SuiteRunner.privateRun(SuiteRunner.java:310)
	at org.testng.SuiteRunner.run(SuiteRunner.java:259)
	at org.testng.SuiteRunnerWorker.runSuite(SuiteRunnerWorker.java:52)
	at org.testng.SuiteRunnerWorker.run(SuiteRunnerWorker.java:86)
	at org.testng.TestNG.runSuitesSequentially(TestNG.java:1176)
	at org.testng.TestNG.runSuitesLocally(TestNG.java:1101)
	at org.testng.TestNG.run(TestNG.java:1009)
	at org.testng.remote.RemoteTestNG.run(RemoteTestNG.java:111)
	at org.testng.remote.RemoteTestNG.initAndRun(RemoteTestNG.java:204)
	at org.testng.remote.RemoteTestNG.main(RemoteTestNG.java:175)
]]>
    </failure>
  </testcase> <!-- EmployeeTest5 -->
  <testcase name="EmployeeTest3" time="0.000" classname="myApplicationTest.TestSuiteAllTests"/>
  <testcase name="EmployeeTest8" time="0.000" classname="myApplicationTest.TestSuiteAllTests"/>
  <testcase name="EmployeeTest4" time="0.000" classname="myApplicationTest.TestSuiteAllTests"/>
  <testcase name="EmployeeTest10" time="0.000" classname="myApplicationTest.TestSuiteAllTests"/>
  <testcase name="EmployeeTest6" time="0.000" classname="myApplicationTest.TestSuiteAllTests"/>
  <testcase name="EmployeeTest9" time="0.010" classname="myApplicationTest.TestSuiteAllTests">
    <failure type="java.lang.AssertionError" message="expected [1000000.0] but found [974.709]">
      <![CDATA[java.lang.AssertionError: expected [1000000.0] but found [974.709]
	at org.testng.Assert.fail(Assert.java:94)
	at org.testng.Assert.failNotEquals(Assert.java:496)
	at org.testng.Assert.assertEquals(Assert.java:209)
	at org.testng.Assert.assertEquals(Assert.java:222)
	at myApplicationTest.TestSuiteAllTests.EmployeeTest9(TestSuiteAllTests.java:85)
	at sun.reflect.NativeMethodAccessorImpl.invoke0(Native Method)
	at sun.reflect.NativeMethodAccessorImpl.invoke(Unknown Source)
	at sun.reflect.DelegatingMethodAccessorImpl.invoke(Unknown Source)
	at java.lang.reflect.Method.invoke(Unknown Source)
	at org.testng.internal.MethodInvocationHelper.invokeMethod(MethodInvocationHelper.java:85)
	at org.testng.internal.Invoker.invokeMethod(Invoker.java:648)
	at org.testng.internal.Invoker.invokeTestMethod(Invoker.java:834)
	at org.testng.internal.Invoker.invokeTestMethods(Invoker.java:1142)
	at org.testng.internal.TestMethodWorker.invokeTestMethods(TestMethodWorker.java:124)
	at org.testng.internal.TestMethodWorker.run(TestMethodWorker.java:108)
	at org.testng.TestRunner.privateRun(TestRunner.java:771)
	at org.testng.TestRunner.run(TestRunner.java:621)
	at org.testng.SuiteRunner.runTest(SuiteRunner.java:357)
	at org.testng.SuiteRunner.runSequentially(SuiteRunner.java:352)
	at org.testng.SuiteRunner.privateRun(SuiteRunner.java:310)
	at org.testng.SuiteRunner.run(SuiteRunner.java:259)
	at org.testng.SuiteRunnerWorker.runSuite(SuiteRunnerWorker.java:52)
	at org.testng.SuiteRunnerWorker.run(SuiteRunnerWorker.java:86)
	at org.testng.TestNG.runSuitesSequentially(TestNG.java:1176)
	at org.testng.TestNG.runSuitesLocally(TestNG.java:1101)
	at org.testng.TestNG.run(TestNG.java:1009)
	at org.testng.remote.RemoteTestNG.run(RemoteTestNG.java:111)
	at org.testng.remote.RemoteTestNG.initAndRun(RemoteTestNG.java:204)
	at org.testng.remote.RemoteTestNG.main(RemoteTestNG.java:175)
]]>
    </failure>
  </testcase> <!-- EmployeeTest9 -->
  <testcase name="waitLongTime" time="1.021" classname="myApplicationTest.TestSuiteAllTests">
    <error type="org.testng.internal.thread.ThreadTimeoutException" message="Method org.testng.internal.TestNGMethod.waitLongTime() didn&#039;t finish within the time-out 1000">
      <![CDATA[org.testng.internal.thread.ThreadTimeoutException: Method org.testng.internal.TestNGMethod.waitLongTime() didn't finish within the time-out 1000
]]>
    </error>
  </testcase> <!-- waitLongTime -->
</testsuite> <!-- myApplicationTest.TestSuiteAllTests -->
